Workbook

Sheet Budget 2023-2024
A1: Product | B1: Product Number | C1: 202307 | D1: 202308 | E1: 202309 | F1: 202310 | G1: 202311 | H1: 202312 | I1: 202401 | J1: 202402 | K1: 202403 | L1: 202404 | M1: 202405 | N1: 202406
A2: Alice Mutton | B2: 17 | C2: 34320 | E2: 10296 | F2: 18876 | G2: 6864 | H2: 40772.16 | I2: 16473.6 | J2: 18189.6 | K2: 9266.4 | L2: 4118.4 | M2: 26426.4 | N2: 37752
A3: Aniseed Syrup | B3: 3 | C3: 1232 | F3: 528 | G3: 1760 | H3: 1760 | I3: 6952 | L3: 2200 | M3: 352 | N3: 1355.2
A4: Boston Crab Meat | B4: 40 | C4: 6800.64 | D4: 9715.2 | E4: 23316.48 | G4: 16030.08 | H4: 161.92 | I4: 18620.8 | J4: 16677.76 | K4: 4857.6 | L4: 8905.6 | N4: 7480.704
A5: Camembert Pierrot | B5: 60 | C5: 37400 | D5: 8976 | E5: 40392 | F5: 2992 | G5: 19448 | H5: 4488 | I5: 46675.2 | J5: 29920 | K5: 32912 | L5: 52060.8 | M5: 598.4 | N5: 41140
A6: Carnarvon Tigers | B6: 18 | C6: 22000 | D6: 45100 | F6: 6600 | G6: 24750 | H6: 16500 | I6: 30250 | J6: 13750 | K6: 9900 | L6: 29150 | N6: 24200
A7: Chai | B7: 1 | C7: 4593.6 | D7: 6336 | F7: 11088 | G7: 9187.2 | I7: 13305.6 | J7: 14256 | K7: 12830.4 | L7: 16473.6 | M7: 6336 | N7: 5052.96
A8: Chang | B8: 2 | C8: 1672 | D8: 16720 | F8: 6353.6 | G8: 2508 | H8: 14212 | I8: 10366.4 | J8: 10199.2 | K8: 1672 | L8: 33607.2 | M8: 10366.4 | N8: 1839.2
A9: Chartreuse verte | B9: 39 | C9: 792 | D9: 3168 | E9: 3643.2 | H9: 23443.2 | I9: 9345.6 | J9: 21067.2 | K9: 4752 | M9: 3484.8 | N9: 871.2
A10: Chef Anton's Cajun Seasoning | B10: 4 | C10: 3872 | D10: 6776 | E10: 2323.2 | F10: 1161.6 | G10: 4840 | I10: 4065.6 | J10: 5808 | K10: 968 | L10: 4840 | M10: 193.6 | N10: 4259.2
A11: Chef Anton's Gumbo Mix | B11: 5 | D11: 2818.2 | F11: 751.52 | I11: 5636.4 | K11: 3757.6 | L11: 18788 | N11: 0
A12: Chocolade | B12: 48 | C12: 673.2 | F12: 2692.8 | I12: 897.6 | N12: 740.52
A13: Côte de Blaye | B13: 38 | C13: 34782 | E13: 34782 | H13: 34782 | I13: 162316 | J13: 231880 | K13: 150722 | L13: 57970 | N13: 38260.2
A14: Escargots de Bourgogne | B14: 58 | C14: 3498 | D14: 699.6 | E14: 9211.4 | F14: 4897.2 | I14: 10494 | J14: 4897.2 | K14: 3498 | L14: 4664 | N14: 3847.8
A15: Filo Mix | B15: 52 | C15: 1724.8 | D15: 308 | E15: 554.4 | F15: 246.4 | G15: 6344.8 | H15: 1416.8 | I15: 1724.8 | J15: 862.4 | K15: 3880.8 | L15: 1971.2 | M15: 123.2 | N15: 1897.28
A16: Fløtemysost | B16: 71 | C16: 7378.8 | D16: 12298 | E16: 4919.2 | F16: 22325.6 | H16: 5297.6 | I16: 10406 | J16: 10406 | K16: 6622 | L16: 37272.4 | N16: 8116.68
A17: Geitost | B17: 33 | C17: 308 | D17: 440 | E17: 1496 | I17: 1210 | J17: 1540 | K17: 484 | L17: 1210 | N17: 338.8
A18: Genen Shouyu | B18: 15 | C18: 3410 | E18: 6820 | N18: 3751
A19: Gnocchi di nonna Alice | B19: 56 | C19: 15716.8 | D19: 33774.4 | E19: 19060.8 | F19: 22739.2 | G19: 32436.8 | H19: 33440 | I19: 34777.6 | J19: 12372.8 | K19: 10032 | L19: 8360 | N19: 17288.48
A20: Gorgonzola Telino | B20: 31 | E20: 5280 | F20: 7700 | G20: 1210 | H20: 16390 | I20: 8140 | J20: 3850 | K20: 16830 | L20: 1650 | M20: 2200 | N20: 0
A21: Grandma's Boysenberry Spread | B21: 6 | D21: 15400 | G21: 6600 | I21: 1320 | J21: 11000 | K21: 19360 | M21: 4620 | N21: 0
A22: Gravad lax | B22: 37 | I22: 13728 | K22: 1830.4 | N22: 0
A23: Guaraná Fantástica | B23: 24 | C23: 1386 | D23: 910.8 | F23: 2178 | H23: 1584 | I23: 1584 | J23: 5781.6 | K23: 7920 | L23: 5544 | M23: 792 | N23: 1524.6
A24: Gudbrandsdalsost | B24: 69 | C24: 26928 | D24: 6336 | E24: 14256 | F24: 17424 | G24: 37382.4 | H24: 7603.2 | J24: 15840 | K24: 6019.2 | L24: 20908.8 | N24: 29620.8
A25: Gula Malacca | B25: 44 | D25: 1711.6 | E25: 8386.84 | F25: 12665.84 | G25: 2738.56 | H25: 1711.6 | I25: 2738.56 | K25: 4107.84 | L25: 4621.32 | N25: 0
A26: Gumbär Gummibärchen | B26: 26 | C26: 3023.064 | D26: 9618.84 | E26: 12367.08 | F26: 12367.08 | G26: 8794.368 | H26: 5771.304 | I26: 28856.52 | J26: 5496.48 | K26: 1374.12 | L26: 22260.744 | N26: 3325.3704
A27: Gustaf's Knäckebröd | B27: 22 | C27: 8870.4 | D27: 17556 | E27: 3696 | H27: 1848 | I27: 16077.6 | K27: 3880.8 | L27: 4620 | N27: 9757.44
A28: Ikura | B28: 10 | C28: 21824 | D28: 4910.4 | E28: 12548.8 | F28: 19914.4 | H28: 14185.6 | I28: 35736.8 | J28: 21824 | K28: 20460 | L28: 6547.2 | M28: 272.8 | N28: 24006.4
A29: Inlagd Sill | B29: 36 | C29: 12707.2 | D29: 2508 | E29: 6019.2 | F29: 7524 | G29: 4347.2 | H29: 5016 | I29: 8360 | J29: 3344 | K29: 15884 | L29: 11536.8 | N29: 13977.92
A30: Ipoh Coffee | B30: 43 | D30: 8096 | E30: 2428.8 | F30: 25907.2 | H30: 12144 | I30: 16596.8 | K30: 19835.2 | L30: 24288 | M30: 14572.8 | N30: 0
A31: Jack's New England Clam Chowder | B31: 41 | E31: 14266.56 | F31: 4585.68 | G31: 3991.24 | H31: 6284.08 | I31: 4415.84 | J31: 4161.08 | K31: 3396.8 | L31: 9595.96 | M31: 5434.88 | N31: 0
A32: Konbu | B32: 13 | C32: 3590.4 | D32: 686.4 | G32: 528 | H32: 1056 | I32: 4804.8 | J32: 3854.4 | K32: 15206.4 | L32: 10190.4 | M32: 739.2 | N32: 3949.44
A33: Lakkalikööri | B33: 76 | C33: 14889.6 | D33: 5544 | E33: 1584 | F33: 7920 | G33: 7920 | I33: 14414.4 | J33: 1584 | K33: 22017.6 | L33: 23126.4 | M33: 316.8 | N33: 16378.56
A34: Laughing Lumberjack Lager | B34: 67 | E34: 3080 | H34: 369.6 | J34: 3696 | K34: 7884.8 | L34: 2464 | N34: 0
A35: Longlife Tofu | B35: 74 | G35: 440 | H35: 4400 | I35: 1760 | L35: 1760 | N35: 0
A36: Louisiana Fiery Hot Pepper Sauce | B36: 65 | C36: 2222.88 | D36: 3890.04 | E36: 6853.88 | F36: 12040.6 | G36: 9262 | H36: 15189.68 | I36: 2778.6 | J36: 11855.36 | L36: 3890.04 | N36: 2445.168
A37: Louisiana Hot Spiced Okra | B37: 66 | E37: 598.4 | H37: 7480 | M37: 149.6 | N37: 0
A38: Manjimup Dried Apples | B38: 51 | D38: 6996 | E38: 18656 | F38: 16324 | G38: 13992 | H38: 87683.2 | I38: 6063.2 | J38: 932.8 | K38: 34513.6 | L38: 62031.2 | N38: 0
A39: Mascarpone Fabioli | B39: 32 | F39: 1126.4 | G39: 2816 | I39: 5632 | J39: 1689.6 | K39: 9856 | L39: 23936 | M39: 281.6 | N39: 0
A40: Maxilaku | B40: 49 | C40: 7568 | H40: 704 | J40: 15312 | K40: 11968 | L40: 10912 | N40: 8324.8
...

Sheet Budget 2022-2023
A1: Product | B1: Product Number | C1: 202207 | D1: 202208 | E1: 202209 | F1: 202210 | G1: 202211 | H1: 202212 | I1: 202301 | J1: 202302 | K1: 202303 | L1: 202304 | M1: 202305 | N1: 202306
A2: Alice Mutton | B2: 17 | C2: ='Budget 2023-2024'!C2 *0.9 -> 30888 | D2: ='Budget 2023-2024'!D2 *0.9 -> 0 | E2: ='Budget 2023-2024'!E2 *0.9 -> 9266.4 | F2: ='Budget 2023-2024'!F2 *0.9 -> 16988.4 | G2: ='Budget 2023-2024'!G2 *0.9 -> 6177.6 | H2: ='Budget 2023-2024'!H2 *0.9 -> 36694.944 | I2: ='Budget 2023-2024'!I2 *0.9 -> 14826.24 | J2: ='Budget 2023-2024'!J2 *0.9 -> 16370.64 | ... N2: ='Budget 2023-2024'!N2 *0.9 -> 33976.8
A3: Aniseed Syrup | B3: 3 | C3: ='Budget 2023-2024'!C3 *0.9 -> 1108.8 | D3: ='Budget 2023-2024'!D3 *0.9 -> 0 | E3: ='Budget 2023-2024'!E3 *0.9 -> 0 | F3: ='Budget 2023-2024'!F3 *0.9 -> 475.2 | G3: ='Budget 2023-2024'!G3 *0.9 -> 1584 | H3: ='Budget 2023-2024'!H3 *0.9 -> 1584 | I3: ='Budget 2023-2024'!I3 *0.9 -> 6256.8 | J3: ='Budget 2023-2024'!J3 *0.9 -> 0 | ... N3: ='Budget 2023-2024'!N3 *0.9 -> 1219.68
A4: Boston Crab Meat | B4: 40 | C4: ='Budget 2023-2024'!C4 *0.9 -> 6120.576 | D4: ='Budget 2023-2024'!D4 *0.9 -> 8743.68 | E4: ='Budget 2023-2024'!E4 *0.9 -> 20984.832 | F4: ='Budget 2023-2024'!F4 *0.9 -> 0 | G4: ='Budget 2023-2024'!G4 *0.9 -> 14427.072 | H4: ='Budget 2023-2024'!H4 *0.9 -> 145.728 | I4: ='Budget 2023-2024'!I4 *0.9 -> 16758.72 | J4: ='Budget 2023-2024'!J4 *0.9 -> 15009.984 | ... N4: ='Budget 2023-2024'!N4 *0.9 -> 6732.6336
A5: Camembert Pierrot | B5: 60 | C5: ='Budget 2023-2024'!C5 *0.9 -> 33660 | D5: ='Budget 2023-2024'!D5 *0.9 -> 8078.4 | E5: ='Budget 2023-2024'!E5 *0.9 -> 36352.8 | F5: ='Budget 2023-2024'!F5 *0.9 -> 2692.8 | G5: ='Budget 2023-2024'!G5 *0.9 -> 17503.2 | H5: ='Budget 2023-2024'!H5 *0.9 -> 4039.2 | I5: ='Budget 2023-2024'!I5 *0.9 -> 42007.68 | J5: ='Budget 2023-2024'!J5 *0.9 -> 26928 | ... N5: ='Budget 2023-2024'!N5 *0.9 -> 37026
A6: Carnarvon Tigers | B6: 18 | C6: ='Budget 2023-2024'!C6 *0.9 -> 19800 | D6: ='Budget 2023-2024'!D6 *0.9 -> 40590 | E6: ='Budget 2023-2024'!E6 *0.9 -> 0 | F6: ='Budget 2023-2024'!F6 *0.9 -> 5940 | G6: ='Budget 2023-2024'!G6 *0.9 -> 22275 | H6: ='Budget 2023-2024'!H6 *0.9 -> 14850 | I6: ='Budget 2023-2024'!I6 *0.9 -> 27225 | J6: ='Budget 2023-2024'!J6 *0.9 -> 12375 | ... N6: ='Budget 2023-2024'!N6 *0.9 -> 21780
A7: Chai | B7: 1 | C7: ='Budget 2023-2024'!C7 *0.9 -> 4134.24 | D7: ='Budget 2023-2024'!D7 *0.9 -> 5702.4 | E7: ='Budget 2023-2024'!E7 *0.9 -> 0 | F7: ='Budget 2023-2024'!F7 *0.9 -> 9979.2 | G7: ='Budget 2023-2024'!G7 *0.9 -> 8268.48 | H7: ='Budget 2023-2024'!H7 *0.9 -> 0 | I7: ='Budget 2023-2024'!I7 *0.9 -> 11975.04 | J7: ='Budget 2023-2024'!J7 *0.9 -> 12830.4 | ... N7: ='Budget 2023-2024'!N7 *0.9 -> 4547.664
A8: Chang | B8: 2 | C8: ='Budget 2023-2024'!C8 *0.9 -> 1504.8 | D8: ='Budget 2023-2024'!D8 *0.9 -> 15048 | E8: ='Budget 2023-2024'!E8 *0.9 -> 0 | F8: ='Budget 2023-2024'!F8 *0.9 -> 5718.24 | G8: ='Budget 2023-2024'!G8 *0.9 -> 2257.2 | H8: ='Budget 2023-2024'!H8 *0.9 -> 12790.8 | I8: ='Budget 2023-2024'!I8 *0.9 -> 9329.76 | J8: ='Budget 2023-2024'!J8 *0.9 -> 9179.28 | ... N8: ='Budget 2023-2024'!N8 *0.9 -> 1655.28
A9: Chartreuse verte | B9: 39 | C9: ='Budget 2023-2024'!C9 *0.9 -> 712.8 | D9: ='Budget 2023-2024'!D9 *0.9 -> 2851.2 | E9: ='Budget 2023-2024'!E9 *0.9 -> 3278.88 | F9: ='Budget 2023-2024'!F9 *0.9 -> 0 | G9: ='Budget 2023-2024'!G9 *0.9 -> 0 | H9: ='Budget 2023-2024'!H9 *0.9 -> 21098.88 | I9: ='Budget 2023-2024'!I9 *0.9 -> 8411.04 | J9: ='Budget 2023-2024'!J9 *0.9 -> 18960.48 | ... N9: ='Budget 2023-2024'!N9 *0.9 -> 784.08
A10: Chef Anton's Cajun Seasoning | B10: 4 | C10: ='Budget 2023-2024'!C10 *0.9 -> 3484.8 | D10: ='Budget 2023-2024'!D10 *0.9 -> 6098.4 | E10: ='Budget 2023-2024'!E10 *0.9 -> 2090.88 | F10: ='Budget 2023-2024'!F10 *0.9 -> 1045.44 | G10: ='Budget 2023-2024'!G10 *0.9 -> 4356 | H10: ='Budget 2023-2024'!H10 *0.9 -> 0 | I10: ='Budget 2023-2024'!I10 *0.9 -> 3659.04 | J10: ='Budget 2023-2024'!J10 *0.9 -> 5227.2 | ... N10: ='Budget 2023-2024'!N10 *0.9 -> 3833.28
A11: Chef Anton's Gumbo Mix | B11: 5 | C11: ='Budget 2023-2024'!C11 *0.9 -> 0 | D11: ='Budget 2023-2024'!D11 *0.9 -> 2536.38 | E11: ='Budget 2023-2024'!E11 *0.9 -> 0 | F11: ='Budget 2023-2024'!F11 *0.9 -> 676.368 | G11: ='Budget 2023-2024'!G11 *0.9 -> 0 | H11: ='Budget 2023-2024'!H11 *0.9 -> 0 | I11: ='Budget 2023-2024'!I11 *0.9 -> 5072.76 | J11: ='Budget 2023-2024'!J11 *0.9 -> 0 | ... N11: ='Budget 2023-2024'!N11 *0.9 -> 0
A12: Chocolade | B12: 48 | C12: ='Budget 2023-2024'!C12 *0.9 -> 605.88 | D12: ='Budget 2023-2024'!D12 *0.9 -> 0 | E12: ='Budget 2023-2024'!E12 *0.9 -> 0 | F12: ='Budget 2023-2024'!F12 *0.9 -> 2423.52 | G12: ='Budget 2023-2024'!G12 *0.9 -> 0 | H12: ='Budget 2023-2024'!H12 *0.9 -> 0 | I12: ='Budget 2023-2024'!I12 *0.9 -> 807.84 | J12: ='Budget 2023-2024'!J12 *0.9 -> 0 | ... N12: ='Budget 2023-2024'!N12 *0.9 -> 666.468
A13: Côte de Blaye | B13: 38 | C13: ='Budget 2023-2024'!C13 *0.9 -> 31303.8 | D13: ='Budget 2023-2024'!D13 *0.9 -> 0 | E13: ='Budget 2023-2024'!E13 *0.9 -> 31303.8 | F13: ='Budget 2023-2024'!F13 *0.9 -> 0 | G13: ='Budget 2023-2024'!G13 *0.9 -> 0 | H13: ='Budget 2023-2024'!H13 *0.9 -> 31303.8 | I13: ='Budget 2023-2024'!I13 *0.9 -> 146084.4 | J13: ='Budget 2023-2024'!J13 *0.9 -> 208692 | ... N13: ='Budget 2023-2024'!N13 *0.9 -> 34434.18
... A78: Zaanse koeken | B78: 47 | C78: ='Budget 2023-2024'!C78 *0.9 -> 1128.6 | D78: ='Budget 2023-2024'!D78 *0.9 -> 0 | E78: ='Budget 2023-2024'!E78 *0.9 -> 5342.04 | F78: ='Budget 2023-2024'!F78 *0.9 -> 5041.08 | G78: ='Budget 2023-2024'!G78 *0.9 -> 2257.2 | H78: ='Budget 2023-2024'!H78 *0.9 -> 2257.2 | I78: ='Budget 2023-2024'!I78 *0.9 -> 3009.6 | J78: ='Budget 2023-2024'!J78 *0.9 -> 1580.04 | ... N78: ='Budget 2023-2024'!N78 *0.9 -> 1241.46
